Workbook

Sheet Guia de Uso
B2: GUIA DE USO — Ejemplo de Registro de Tiempos de Ejecucion
B3: Estructura de Datos | Ing. Brandon Chitay | Universidad Da Vinci de Guatemala
B5: PROPOSITO DEL ARCHIVO | C5: Este archivo te muestra EXACTAMENTE como registrar tus tiempos, calcular promedios y generar las graficas. Los datos de muestra son ficticios (realistas pero inventados). Reemplazalos con los tiempos reales que obtengas al ejecutar tus algoritmos en Java.
B8: ESTRUCTURA DEL LIBRO | C8: 1. Datos_Crudos — tabla con las 5 ejecuciones y el promedio por algoritmo 2. Factorial — comparativa iterativo vs recursivo + grafica 3. Fibonacci — comparativa + grafica (ven la diferencia exponencial!) 4. Busqueda_Lineal — comparativa + grafica 5. Burbuja — comparativa + grafica 6. Conclusiones — tabla de Big-O experimental vs teorico
B11: CODIGO DE COLORES | C11: Fondo AMARILLO → Celdas que TU debes rellenar con tus mediciones reales Fondo VERDE → Formula automatica (promedio), NO la edites Fondo AZUL → Encabezado, no modificar Fondo GRIS → Dato de referencia calculado automaticamente
B14: COMO MEDIR EN JAVA | C14: long inicio = System.nanoTime(); // ... tu algoritmo aqui ... long fin = System.nanoTime(); double ms = (fin - inicio) / 1_000_000.0; Repite 5 veces y registra cada resultado en las columnas Ej.1 a Ej.5.
B17: COMO CREAR LA GRAFICA | C17: 1. Selecciona las columnas n, Iterativo y Recursivo de la hoja comparativa 2. Insertar → Grafico → Dispersion con lineas y marcadores 3. Agrega titulo: '[Algoritmo]: Iterativo vs Recursivo' 4. Eje X: Tamano (n) | Eje Y: Tiempo (ms) 5. Clic derecho en cada serie → Agregar linea de tendencia
B20: PREGUNTAS CLAVE | C20: Fibonacci: ¿por que el recursivo es tan mas lento que el iterativo? Burbuja: ¿cuanto aumenta el tiempo al duplicar n? (pista: 4x) ¿Cual algoritmo es el mas rapido? ¿El mas lento? ¿Vale la pena la elegancia del codigo recursivo para Fibonacci?

Sheet tiempos1
A1: Algoritmo | B1: Version | C1: n | D1: Tiempo_ms
A2: A1 - Factorial | B2: Iterativo | C2: 5 | D2: 0.09484
A3: A1 - Factorial | B3: Iterativo | C3: 10 | D3: 0.00048
A4: A1 - Factorial | B4: Iterativo | C4: 15 | D4: 0.00072
A5: A1 - Factorial | B5: Iterativo | C5: 20 | D5: 0.00058
A6: A1 - Factorial | B6: Iterativo | C6: 25 | D6: 0.00056
A7: A1 - Factorial | B7: Iterativo | C7: 30 | D7: 0.00082
A8: A1 - Factorial | B8: Recursivo | C8: 5 | D8: 0.00112
A9: A1 - Factorial | B9: Recursivo | C9: 10 | D9: 0.00062
A10: A1 - Factorial | B10: Recursivo | C10: 15 | D10: 0.00128
A11: A1 - Factorial | B11: Recursivo | C11: 20 | D11: 0.00116
A12: A1 - Factorial | B12: Recursivo | C12: 25 | D12: 0
A13: A1 - Factorial | B13: Recursivo | C13: 30 | D13: 0
... A45: A4 - Burbuja | B45: Recursivo | C45: 10000 | D45: 106.8381

Sheet 1. Datos_Crudos
B1: HOJA 1 — Datos Crudos | Tiempos de Ejecucion (ms)
B2: Algoritmo | C2: Version | D2: n | E2: Ej. 1 (ms) | F2: Ej. 2 (ms) | G2: Ej. 3 (ms) | H2: Ej. 4 (ms) | I2: Ej. 5 (ms) | J2: PROMEDIO (ms)
B3: A1 - Factorial | C3: Iterativo | D3: 5 | E3: =tiempos1!D2 -> 0.09484 | F3: 0 | G3: 0 | H3: 0 | I3: 0 | J3: =AVERAGE(E3:I3) -> 0.018968
B4: A1 - Factorial | C4: Iterativo | D4: 10 | E4: =tiempos1!D3 -> 0.00048 | F4: 0 | G4: 0 | H4: 0 | I4: 0 | J4: =AVERAGE(E4:I4) -> 9.6e-05
B5: A1 - Factorial | C5: Iterativo | D5: 15 | E5: =tiempos1!D4 -> 0.00072 | F5: 0 | G5: 0 | H5: 0 | I5: 0 | J5: =AVERAGE(E5:I5) -> 0.000144
B6: A1 - Factorial | C6: Iterativo | D6: 20 | E6: =tiempos1!D5 -> 0.00058 | F6: 0 | G6: 0 | H6: 0 | I6: 0 | J6: =AVERAGE(E6:I6) -> 0.000116
B7: A1 - Factorial | C7: Iterativo | D7: 25 | E7: =tiempos1!D6 -> 0.00056 | F7: 0 | G7: 0 | H7: 0 | I7: 0 | J7: =AVERAGE(E7:I7) -> 0.000112
B8: A1 - Factorial | C8: Iterativo | D8: 30 | E8: =tiempos1!D7 -> 0.00082 | F8: 0 | G8: 0 | H8: 0 | I8: 0 | J8: =AVERAGE(E8:I8) -> 0.000164
B9: A1 - Factorial | C9: Recursivo | D9: 5 | E9: =tiempos1!D8 -> 0.00112 | F9: 0 | G9: 0 | H9: 0 | I9: 0 | J9: =AVERAGE(E9:I9) -> 0.000224
B10: A1 - Factorial | C10: Recursivo | D10: 10 | E10: =tiempos1!D9 -> 0.00062 | F10: 0 | G10: 0 | H10: 0 | I10: 0 | J10: =AVERAGE(E10:I10) -> 0.000124
B11: A1 - Factorial | C11: Recursivo | D11: 15 | E11: =tiempos1!D10 -> 0.00128 | F11: 0 | G11: 0 | H11: 0 | I11: 0 | J11: =AVERAGE(E11:I11) -> 0.000256
B12: A1 - Factorial | C12: Recursivo | D12: 20 | E12: =tiempos1!D11 -> 0.00116 | F12: 0 | G12: 0 | H12: 0 | I12: 0 | J12: =AVERAGE(E12:I12) -> 0.000232
B13: A1 - Factorial | C13: Recursivo | D13: 25 | E13: =tiempos1!D12 -> 0 | F13: 0 | G13: 0 | H13: 0 | I13: 0 | J13: =AVERAGE(E13:I13) -> 0
B14: A1 - Factorial | C14: Recursivo | D14: 30 | E14: =tiempos1!D13 -> 0 | F14: 0 | G14: 0 | H14: 0 | I14: 0 | J14: =AVERAGE(E14:I14) -> 0
B16: A2 - Fibonacci | C16: Iterativo | D16: 5 | E16: =tiempos1!D14 -> 0.1172 | F16: 0 | G16: 0 | H16: 0 | I16: 0 | J16: =AVERAGE(E16:I16) -> 0.02344
B17: A2 - Fibonacci | C17: Iterativo | D17: 10 | E17: =tiempos1!D15 -> 0.00044 | F17: 0 | G17: 0 | H17: 0 | I17: 0 | J17: =AVERAGE(E17:I17) -> 8.8e-05
B18: A2 - Fibonacci | C18: Iterativo | D18: 15 | E18: =tiempos1!D16 -> 0.00138 | F18: 0 | G18: 0 | H18: 0 | I18: 0 | J18: =AVERAGE(E18:I18) -> 0.000276
B19: A2 - Fibonacci | C19: Iterativo | D19: 20 | E19: =tiempos1!D17 -> 0.00078 | F19: 0 | G19: 0 | H19: 0 | I19: 0 | J19: =AVERAGE(E19:I19) -> 0.000156
B20: A2 - Fibonacci | C20: Iterativo | D20: 25 | E20: =tiempos1!D18 -> 0.00092 | F20: 0 | G20: 0 | H20: 0 | I20: 0 | J20: =AVERAGE(E20:I20) -> 0.000184
B21: A2 - Fibonacci | C21: Iterativo | D21: 30 | E21: =tiempos1!D19 -> 0.00098 | F21: 0 | G21: 0 | H21: 0 | I21: 0 | J21: =AVERAGE(E21:I21) -> 0.000196
B22: A2 - Fibonacci | C22: Recursivo | D22: 5 | E22: =tiempos1!D20 -> 0.00166 | F22: 0 | G22: 0 | H22: 0 | I22: 0 | J22: =AVERAGE(E22:I22) -> 0.000332
B23: A2 - Fibonacci | C23: Recursivo | D23: 10 | E23: =tiempos1!D21 -> 0.02506 | F23: 0 | G23: 0 | H23: 0 | I23: 0 | J23: =AVERAGE(E23:I23) -> 0.005012
B24: A2 - Fibonacci | C24: Recursivo | D24: 15 | E24: =tiempos1!D22 -> 0.0126 | F24: 0 | G24: 0 | H24: 0 | I24: 0 | J24: =AVERAGE(E24:I24) -> 0.00252
B25: A2 - Fibonacci | C25: Recursivo | D25: 20 | E25: =tiempos1!D23 -> 0.0481 | F25: 0 | G25: 0 | H25: 0 | I25: 0 | J25: =AVERAGE(E25:I25) -> 0.00962
B26: A2 - Fibonacci | C26: Recursivo | D26: 25 | E26: =tiempos1!D24 -> 0.3435 | F26: 0 | G26: 0 | H26: 0 | I26: 0 | J26: =AVERAGE(E26:I26) -> 0.0687
B27: A2 - Fibonacci | C27: Recursivo | D27: 30 | E27: =tiempos1!D25 -> 3.64746 | F27: 0 | G27: 0 | H27: 0 | I27: 0 | J27: =AVERAGE(E27:I27) -> 0.729492
B29: A3 - Busqueda Lineal | C29: Iterativo | D29: 100 | E29: =tiempos1!D26 -> 0.1212 | F29: 0 | G29: 0 | H29: 0 | I29: 0 | J29: =AVERAGE(E29:I29) -> 0.02424
B30: A3 - Busqueda Lineal | C30: Iterativo | D30: 500 | E30: =tiempos1!D27 -> 0.00662 | F30: 0 | G30: 0 | H30: 0 | I30: 0 | J30: =AVERAGE(E30:I30) -> 0.001324
B31: A3 - Busqueda Lineal | C31: Iterativo | D31: 1000 | E31: =tiempos1!D28 -> 0.01272 | F31: 0 | G31: 0 | H31: 0 | I31: 0 | J31: =AVERAGE(E31:I31) -> 0.002544
B32: A3 - Busqueda Lineal | C32: Iterativo | D32: 5000 | E32: =tiempos1!D29 -> 0.06164 | F32: 0 | G32: 0 | H32: 0 | I32: 0 | J32: =AVERAGE(E32:I32) -> 0.012328
B33: A3 - Busqueda Lineal | C33: Iterativo | D33: 10000 | E33: =tiempos1!D30 -> 0.14342 | F33: 0 | G33: 0 | H33: 0 | I33: 0 | J33: =AVERAGE(E33:I33) -> 0.028684
B34: A3 - Busqueda Lineal | C34: Recursivo | D34: 100 | E34: =tiempos1!D31 -> 0.00726 | F34: 0 | G34: 0 | H34: 0 | I34: 0 | J34: =AVERAGE(E34:I34) -> 0.001452
B35: A3 - Busqueda Lineal | C35: Recursivo | D35: 500 | E35: =tiempos1!D32 -> 0.0084 | F35: 0 | G35: 0 | H35: 0 | I35: 0 | J35: =AVERAGE(E35:I35) -> 0.00168
B36: A3 - Busqueda Lineal | C36: Recursivo | D36: 1000 | E36: =tiempos1!D33 -> 0.01676 | F36: 0 | G36: 0 | H36: 0 | I36: 0 | J36: =AVERAGE(E36:I36) -> 0.003352
B37: A3 - Busqueda Lineal | C37: Recursivo | D37: 5000 | E37: =tiempos1!D34 -> 0.06792 | F37: 0 | G37: 0 | H37: 0 | I37: 0 | J37: =AVERAGE(E37:I37) -> 0.013584
B38: A3 - Busqueda Lineal | C38: Recursivo | D38: 10000 | E38: =tiempos1!D35 -> 0.0655 | F38: 0 | G38: 0 | H38: 0 | I38: 0 | J38: =AVERAGE(E38:I38) -> 0.0131
B40: A4 - Burbuja | C40: Iterativo | D40: 100 | E40: =tiempos1!D36 -> 0.29004 | F40: 0 | G40: 0 | H40: 0 | I40: 0 | J40: =AVERAGE(E40:I40) -> 0.058008
B41: A4 - Burbuja | C41: Iterativo | D41: 500 | E41: =tiempos1!D37 -> 0.86792 | F41: 0 | G41: 0 | H41: 0 | I41: 0 | J41: =AVERAGE(E41:I41) -> 0.173584
B42: A4 - Burbuja | C42: Iterativo | D42: 1000 | E42: =tiempos1!D38 -> 1.4627 | F42: 0 | G42: 0 | H42: 0 | I42: 0 | J42: =AVERAGE(E42:I42) -> 0.29254
B43: A4 - Burbuja | C43: Iterativo | D43: 5000 | E43: =tiempos1!D39 -> 24.7875 | F43: 0 | G43: 0 | H43: 0 | I43: 0 | J43: =AVERAGE(E43:I43) -> 4.9575
...

Sheet 2. Factorial
B1: HOJA — A1 - Factorial | Iterativo vs. Recursivo
B2: Big-O Iterativo: | C2: O(n) | D2: Big-O Recursivo: O(n)
B4: n | C4: Iterativo (O(n)) | D4: Recursivo (O(n))
B5: 5 | C5: =AVERAGEIFS('1. Datos_Crudos'!$J:$J,'1. Datos_Crudos'!$B:$B,"A1 - Factorial",'1. Datos_Crudos'!$C:$C,"Iterativo",'1. Datos_Crudos'!$D:$D,B5) -> 0.018968 | D5: =AVERAGEIFS('1. Datos_Crudos'!$J:$J,'1. Datos_Crudos'!$B:$B,"A1 - Factorial",'1. Datos_Crudos'!$C:$C,"Recursivo",'1. Datos_Crudos'!$D:$D,B5) -> 0.000224
B6: 10 | C6: =AVERAGEIFS('1. Datos_Crudos'!$J:$J,'1. Datos_Crudos'!$B:$B,"A1 - Factorial",'1. Datos_Crudos'!$C:$C,"Iterativo",'1. Datos_Crudos'!$D:$D,B6) -> 9.6e-05 | D6: =AVERAGEIFS('1. Datos_Crudos'!$J:$J,'1. Datos_Crudos'!$B:$B,"A1 - Factorial",'1. Datos_Crudos'!$C:$C,"Recursivo",'1. Datos_Crudos'!$D:$D,B6) -> 0.000124
B7: 15 | C7: =AVERAGEIFS('1. Datos_Crudos'!$J:$J,'1. Datos_Crudos'!$B:$B,"A1 - Factorial",'1. Datos_Crudos'!$C:$C,"Iterativo",'1. Datos_Crudos'!$D:$D,B7) -> 0.000144 | D7: =AVERAGEIFS('1. Datos_Crudos'!$J:$J,'1. Datos_Crudos'!$B:$B,"A1 - Factorial",'1. Datos_Crudos'!$C:$C,"Recursivo",'1. Datos_Crudos'!$D:$D,B7) -> 0.000256
B8: 20 | C8: =AVERAGEIFS('1. Datos_Crudos'!$J:$J,'1. Datos_Crudos'!$B:$B,"A1 - Factorial",'1. Datos_Crudos'!$C:$C,"Iterativo",'1. Datos_Crudos'!$D:$D,B8) -> 0.000116 | D8: =AVERAGEIFS('1. Datos_Crudos'!$J:$J,'1. Datos_Crudos'!$B:$B,"A1 - Factorial",'1. Datos_Crudos'!$C:$C,"Recursivo",'1. Datos_Crudos'!$D:$D,B8) -> 0.000232
B9: 25 | C9: =AVERAGEIFS('1. Datos_Crudos'!$J:$J,'1. Datos_Crudos'!$B:$B,"A1 - Factorial",'1. Datos_Crudos'!$C:$C,"Iterativo",'1. Datos_Crudos'!$D:$D,B9) -> 0.000112 | D9: =AVERAGEIFS('1. Datos_Crudos'!$J:$J,'1. Datos_Crudos'!$B:$B,"A1 - Factorial",'1. Datos_Crudos'!$C:$C,"Recursivo",'1. Datos_Crudos'!$D:$D,B9) -> 0
B10: 30 | C10: =AVERAGEIFS('1. Datos_Crudos'!$J:$J,'1. Datos_Crudos'!$B:$B,"A1 - Factorial",'1. Datos_Crudos'!$C:$C,"Iterativo",'1. Datos_Crudos'!$D:$D,B10) -> 0.000164 | D10: =AVERAGEIFS('1. Datos_Crudos'!$J:$J,'1. Datos_Crudos'!$B:$B,"A1 - Factorial",'1. Datos_Crudos'!$C:$C,"Recursivo",'1. Datos_Crudos'!$D:$D,B10) -> 0
B12: Observacion: Ambas versiones son O(n): el tiempo crece linealmente con n.

Sheet 3. Fibonacci
B1: HOJA — A2 - Fibonacci | Iterativo vs. Recursivo
B2: Big-O Iterativo: | C2: O(n) | D2: Big-O Recursivo: O(2^n)
B4: n | C4: Iterativo (O(n)) | D4: Recursivo (O(2^n))
B5: 5 | C5: =AVERAGEIFS('1. Datos_Crudos'!$J:$J,'1. Datos_Crudos'!$B:$B,"A2 - Fibonacci",'1. Datos_Crudos'!$C:$C,"Iterativo",'1. Datos_Crudos'!$D:$D,B5) -> 0.02344 | D5: =AVERAGEIFS('1. Datos_Crudos'!$J:$J,'1. Datos_Crudos'!$B:$B,"A2 - Fibonacci",'1. Datos_Crudos'!$C:$C,"Recursivo",'1. Datos_Crudos'!$D:$D,B5) -> 0.000332
B6: 10 | C6: =AVERAGEIFS('1. Datos_Crudos'!$J:$J,'1. Datos_Crudos'!$B:$B,"A2 - Fibonacci",'1. Datos_Crudos'!$C:$C,"Iterativo",'1. Datos_Crudos'!$D:$D,B6) -> 8.8e-05 | D6: =AVERAGEIFS('1. Datos_Crudos'!$J:$J,'1. Datos_Crudos'!$B:$B,"A2 - Fibonacci",'1. Datos_Crudos'!$C:$C,"Recursivo",'1. Datos_Crudos'!$D:$D,B6) -> 0.005012
B7: 15 | C7: =AVERAGEIFS('1. Datos_Crudos'!$J:$J,'1. Datos_Crudos'!$B:$B,"A2 - Fibonacci",'1. Datos_Crudos'!$C:$C,"Iterativo",'1. Datos_Crudos'!$D:$D,B7) -> 0.000276 | D7: =AVERAGEIFS('1. Datos_Crudos'!$J:$J,'1. Datos_Crudos'!$B:$B,"A2 - Fibonacci",'1. Datos_Crudos'!$C:$C,"Recursivo",'1. Datos_Crudos'!$D:$D,B7) -> 0.00252
B8: 20 | C8: =AVERAGEIFS('1. Datos_Crudos'!$J:$J,'1. Datos_Crudos'!$B:$B,"A2 - Fibonacci",'1. Datos_Crudos'!$C:$C,"Iterativo",'1. Datos_Crudos'!$D:$D,B8) -> 0.000156 | D8: =AVERAGEIFS('1. Datos_Crudos'!$J:$J,'1. Datos_Crudos'!$B:$B,"A2 - Fibonacci",'1. Datos_Crudos'!$C:$C,"Recursivo",'1. Datos_Crudos'!$D:$D,B8) -> 0.00962
B9: 25 | C9: =AVERAGEIFS('1. Datos_Crudos'!$J:$J,'1. Datos_Crudos'!$B:$B,"A2 - Fibonacci",'1. Datos_Crudos'!$C:$C,"Iterativo",'1. Datos_Crudos'!$D:$D,B9) -> 0.000184 | D9: =AVERAGEIFS('1. Datos_Crudos'!$J:$J,'1. Datos_Crudos'!$B:$B,"A2 - Fibonacci",'1. Datos_Crudos'!$C:$C,"Recursivo",'1. Datos_Crudos'!$D:$D,B9) -> 0.0687
B10: 30 | C10: =AVERAGEIFS('1. Datos_Crudos'!$J:$J,'1. Datos_Crudos'!$B:$B,"A2 - Fibonacci",'1. Datos_Crudos'!$C:$C,"Iterativo",'1. Datos_Crudos'!$D:$D,B10) -> 0.000196 | D10: =AVERAGEIFS('1. Datos_Crudos'!$J:$J,'1. Datos_Crudos'!$B:$B,"A2 - Fibonacci",'1. Datos_Crudos'!$C:$C,"Recursivo",'1. Datos_Crudos'!$D:$D,B10) -> 0.729492
B12: Observacion: Recursivo crece exponencialmente: duplicar n casi cuadriplica el tiempo.

Sheet 4. Busqueda Lineal
B1: HOJA — A3 - Busqueda Lineal | Iterativo vs. Recursivo
B2: Big-O Iterativo: | C2: O(n) | D2: Big-O Recursivo: O(n)
B4: n | C4: Iterativo (O(n)) | D4: Recursivo (O(n))
B5: 100 | C5: =AVERAGEIFS('1. Datos_Crudos'!$J:$J,'1. Datos_Crudos'!$B:$B,"A3 - Busqueda Lineal",'1. Datos_Crudos'!$C:$C,"Iterativo",'1. Datos_Crudos'!$D:$D,B5) -> 0.02424 | D5: =AVERAGEIFS('1. Datos_Crudos'!$J:$J,'1. Datos_Crudos'!$B:$B,"A3 - Busqueda Lineal",'1. Datos_Crudos'!$C:$C,"Recursivo",'1. Datos_Crudos'!$D:$D,B5) -> 0.001452
B6: 500 | C6: =AVERAGEIFS('1. Datos_Crudos'!$J:$J,'1. Datos_Crudos'!$B:$B,"A3 - Busqueda Lineal",'1. Datos_Crudos'!$C:$C,"Iterativo",'1. Datos_Crudos'!$D:$D,B6) -> 0.001324 | D6: =AVERAGEIFS('1. Datos_Crudos'!$J:$J,'1. Datos_Crudos'!$B:$B,"A3 - Busqueda Lineal",'1. Datos_Crudos'!$C:$C,"Recursivo",'1. Datos_Crudos'!$D:$D,B6) -> 0.00168
B7: 1000 | C7: =AVERAGEIFS('1. Datos_Crudos'!$J:$J,'1. Datos_Crudos'!$B:$B,"A3 - Busqueda Lineal",'1. Datos_Crudos'!$C:$C,"Iterativo",'1. Datos_Crudos'!$D:$D,B7) -> 0.002544 | D7: =AVERAGEIFS('1. Datos_Crudos'!$J:$J,'1. Datos_Crudos'!$B:$B,"A3 - Busqueda Lineal",'1. Datos_Crudos'!$C:$C,"Recursivo",'1. Datos_Crudos'!$D:$D,B7) -> 0.003352
B8: 5000 | C8: =AVERAGEIFS('1. Datos_Crudos'!$J:$J,'1. Datos_Crudos'!$B:$B,"A3 - Busqueda Lineal",'1. Datos_Crudos'!$C:$C,"Iterativo",'1. Datos_Crudos'!$D:$D,B8) -> 0.012328 | D8: =AVERAGEIFS('1. Datos_Crudos'!$J:$J,'1. Datos_Crudos'!$B:$B,"A3 - Busqueda Lineal",'1. Datos_Crudos'!$C:$C,"Recursivo",'1. Datos_Crudos'!$D:$D,B8) -> 0.013584
B9: 10000 | C9: =AVERAGEIFS('1. Datos_Crudos'!$J:$J,'1. Datos_Crudos'!$B:$B,"A3 - Busqueda Lineal",'1. Datos_Crudos'!$C:$C,"Iterativo",'1. Datos_Crudos'!$D:$D,B9) -> 0.028684 | D9: =AVERAGEIFS('1. Datos_Crudos'!$J:$J,'1. Datos_Crudos'!$B:$B,"A3 - Busqueda Lineal",'1. Datos_Crudos'!$C:$C,"Recursivo",'1. Datos_Crudos'!$D:$D,B9) -> 0.0131
B11: Observacion: Ambas O(n): al multiplicar n x10, el tiempo tambien x10 aprox.

Sheet 5. Burbuja
B1: HOJA — A4 - Burbuja | Iterativo vs. Recursivo
B2: Big-O Iterativo: | C2: O(n^2) | D2: Big-O Recursivo: O(n^2)
B4: n | C4: Iterativo (O(n^2)) | D4: Recursivo (O(n^2))
B5: 100 | C5: =AVERAGEIFS('1. Datos_Crudos'!$J:$J,'1. Datos_Crudos'!$B:$B,"A4 - Burbuja",'1. Datos_Crudos'!$C:$C,"Iterativo",'1. Datos_Crudos'!$D:$D,B5) -> 0.058008 | D5: =AVERAGEIFS('1. Datos_Crudos'!$J:$J,'1. Datos_Crudos'!$B:$B,"A4 - Burbuja",'1. Datos_Crudos'!$C:$C,"Recursivo",'1. Datos_Crudos'!$D:$D,B5) -> 0.017228
B6: 500 | C6: =AVERAGEIFS('1. Datos_Crudos'!$J:$J,'1. Datos_Crudos'!$B:$B,"A4 - Burbuja",'1. Datos_Crudos'!$C:$C,"Iterativo",'1. Datos_Crudos'!$D:$D,B6) -> 0.173584 | D6: =AVERAGEIFS('1. Datos_Crudos'!$J:$J,'1. Datos_Crudos'!$B:$B,"A4 - Burbuja",'1. Datos_Crudos'!$C:$C,"Recursivo",'1. Datos_Crudos'!$D:$D,B6) -> 0.108532
B7: 1000 | C7: =AVERAGEIFS('1. Datos_Crudos'!$J:$J,'1. Datos_Crudos'!$B:$B,"A4 - Burbuja",'1. Datos_Crudos'!$C:$C,"Iterativo",'1. Datos_Crudos'!$D:$D,B7) -> 0.29254 | D7: =AVERAGEIFS('1. Datos_Crudos'!$J:$J,'1. Datos_Crudos'!$B:$B,"A4 - Burbuja",'1. Datos_Crudos'!$C:$C,"Recursivo",'1. Datos_Crudos'!$D:$D,B7) -> 0.360264
B8: 5000 | C8: =AVERAGEIFS('1. Datos_Crudos'!$J:$J,'1. Datos_Crudos'!$B:$B,"A4 - Burbuja",'1. Datos_Crudos'!$C:$C,"Iterativo",'1. Datos_Crudos'!$D:$D,B8) -> 4.9575 | D8: =AVERAGEIFS('1. Datos_Crudos'!$J:$J,'1. Datos_Crudos'!$B:$B,"A4 - Burbuja",'1. Datos_Crudos'!$C:$C,"Recursivo",'1. Datos_Crudos'!$D:$D,B8) -> 4.465892
B9: 10000 | C9: =AVERAGEIFS('1. Datos_Crudos'!$J:$J,'1. Datos_Crudos'!$B:$B,"A4 - Burbuja",'1. Datos_Crudos'!$C:$C,"Iterativo",'1. Datos_Crudos'!$D:$D,B9) -> 24.249644 | D9: =AVERAGEIFS('1. Datos_Crudos'!$J:$J,'1. Datos_Crudos'!$B:$B,"A4 - Burbuja",'1. Datos_Crudos'!$C:$C,"Recursivo",'1. Datos_Crudos'!$D:$D,B9) -> 21.36762
B11: Observacion: Ambas O(n^2): al x10 n, el tiempo aumenta aprox x100.

Sheet 6. Conclusiones
B1: HOJA 6 — Conclusiones | Big-O Experimental vs. Teorico
B3: Algoritmo | C3: Version | D3: Big-O Experimental (de tu grafica) | E3: Big-O Teorico | F3: Coincide? | G3: Justificacion breve
B4: A1 - Factorial | C4: Iterativo | D4: O(n) | E4: O(n) | F4: Si | G4: Ambas versiones muestran una línea recta. El tiempo aumenta de forma directamente proporcional al valor de n, lo que confirma una complejidad lineal.
B5: A1 - Factorial | C5: Recursivo | D5: O(n) | E5: O(n) | F5: Si
B6: A2 - Fibonacci | C6: Iterativo | D6: O(n) | E6: O(n) | F6: Si | G6: Se mantiene lineal porque solo recorre un ciclo desde 1 hasta n.
B7: A2 - Fibonacci | C7: Recursivo | D7: O(2^n) | E7: O(2^n) | F7: Si | G7: Se observa un crecimiento exponencial O(2^n) debido a que cada llamada recursiva genera dos nuevas ramas, duplicando el esfuerzo computacional en cada paso.
B8: A3 - Busqueda Lineal | C8: Iterativo | D8: O(n) | E8: O(n) | F8: Si | G8: Al buscar un elemento que no existe (peor caso), el algoritmo recorre todo el arreglo. A mayor tamaño de arreglo, mayor tiempo de forma lineal.
B9: A3 - Busqueda Lineal | C9: Recursivo | D9: O(n) | E9: O(n) | F9: Si
B10: A4 - Burbuja | C10: Iterativo | D10: O(2^n) | E10: O(n^2) | F10: Si | G10: La gráfica muestra una curva que sube mucho más rápido que la lineal (forma de parábola). Esto se debe a los ciclos anidados, donde el tiempo es el cuadrado del tamaño de los datos.
B11: A4 - Burbuja | C11: Recursivo | D11: O(2^n) | E11: O(n^2) | F11: Si
B15: Guia para interpretar tus graficas:
B16: Linea recta en grafica | C16: → Big-O es probablemente O(1) o O(n)
B17: Curva suave ascendente | C17: → Big-O es probablemente O(n) o O(log n)
B18: Curva que sube rapido | C18: → Big-O es probablemente O(n^2)
B19: Curva que explota (vertical) | C19: → Big-O es probablemente O(2^n)
